Workbook

Sheet Summary
A1: E-commerce Store - Test Execution Summary
A2: Run date: 2026-10-19 | Runner: pytest + pytest-django | Database: PostgreSQL | Command: pytest
A4: App / group | B4: Prefix | C4: Total | D4: Pass | E4: Fail | F4: Blocked | G4: Pass rate
A5: authen (auth) | B5: AUTH | C5: =COUNTIF('Test Cases'!$A$2:$A$150,B5&"-*") -> 30 | D5: =COUNTIFS('Test Cases'!$A$2:$A$150,B5&"-*",'Test Cases'!$H$2:$H$150,"PASS") -> 24 | E5: =COUNTIFS('Test Cases'!$A$2:$A$150,B5&"-*",'Test Cases'!$H$2:$H$150,"FAIL") -> 6 | F5: =COUNTIFS('Test Cases'!$A$2:$A$150,B5&"-*",'Test Cases'!$H$2:$H$150,"BLOCKED") -> 0 | G5: =IF(C5=0,0,D5/C5) -> 0.8
A6: carts | B6: CART | C6: =COUNTIF('Test Cases'!$A$2:$A$150,B6&"-*") -> 36 | D6: =COUNTIFS('Test Cases'!$A$2:$A$150,B6&"-*",'Test Cases'!$H$2:$H$150,"PASS") -> 20 | E6: =COUNTIFS('Test Cases'!$A$2:$A$150,B6&"-*",'Test Cases'!$H$2:$H$150,"FAIL") -> 1 | F6: =COUNTIFS('Test Cases'!$A$2:$A$150,B6&"-*",'Test Cases'!$H$2:$H$150,"BLOCKED") -> 15 | G6: =IF(C6=0,0,D6/C6) -> 0.55555556
A7: products | B7: PRD | C7: =COUNTIF('Test Cases'!$A$2:$A$150,B7&"-*") -> 32 | D7: =COUNTIFS('Test Cases'!$A$2:$A$150,B7&"-*",'Test Cases'!$H$2:$H$150,"PASS") -> 30 | E7: =COUNTIFS('Test Cases'!$A$2:$A$150,B7&"-*",'Test Cases'!$H$2:$H$150,"FAIL") -> 2 | F7: =COUNTIFS('Test Cases'!$A$2:$A$150,B7&"-*",'Test Cases'!$H$2:$H$150,"BLOCKED") -> 0 | G7: =IF(C7=0,0,D7/C7) -> 0.9375
A8: inventory | B8: INV | C8: =COUNTIF('Test Cases'!$A$2:$A$150,B8&"-*") -> 14 | D8: =COUNTIFS('Test Cases'!$A$2:$A$150,B8&"-*",'Test Cases'!$H$2:$H$150,"PASS") -> 9 | E8: =COUNTIFS('Test Cases'!$A$2:$A$150,B8&"-*",'Test Cases'!$H$2:$H$150,"FAIL") -> 5 | F8: =COUNTIFS('Test Cases'!$A$2:$A$150,B8&"-*",'Test Cases'!$H$2:$H$150,"BLOCKED") -> 0 | G8: =IF(C8=0,0,D8/C8) -> 0.64285714
A9: orders | B9: ORD | C9: =COUNTIF('Test Cases'!$A$2:$A$150,B9&"-*") -> 29 | D9: =COUNTIFS('Test Cases'!$A$2:$A$150,B9&"-*",'Test Cases'!$H$2:$H$150,"PASS") -> 28 | E9: =COUNTIFS('Test Cases'!$A$2:$A$150,B9&"-*",'Test Cases'!$H$2:$H$150,"FAIL") -> 1 | F9: =COUNTIFS('Test Cases'!$A$2:$A$150,B9&"-*",'Test Cases'!$H$2:$H$150,"BLOCKED") -> 0 | G9: =IF(C9=0,0,D9/C9) -> 0.96551724
A10: rate limiter | B10: RL | C10: =COUNTIF('Test Cases'!$A$2:$A$150,B10&"-*") -> 8 | D10: =COUNTIFS('Test Cases'!$A$2:$A$150,B10&"-*",'Test Cases'!$H$2:$H$150,"PASS") -> 0 | E10: =COUNTIFS('Test Cases'!$A$2:$A$150,B10&"-*",'Test Cases'!$H$2:$H$150,"FAIL") -> 0 | F10: =COUNTIFS('Test Cases'!$A$2:$A$150,B10&"-*",'Test Cases'!$H$2:$H$150,"BLOCKED") -> 8 | G10: =IF(C10=0,0,D10/C10) -> 0
A11: TOTAL | C11: =SUM(C5:C10) -> 149 | D11: =SUM(D5:D10) -> 111 | E11: =SUM(E5:E10) -> 15 | F11: =SUM(F5:F10) -> 23 | G11: =IF(C11=0,0,D11/C11) -> 0.74496644
A13: How to read this:
A14: PASS = automated assertions passed. FAIL = the app behaved differently from the expected result (see Defects sheet).
A15: BLOCKED = result is not trustworthy because of a test-setup problem (wrong URL constant or module path). These are re-run items, not app results.
A16: Five cart tests (CART-33, 34, 35, 42, 43) were reported as passed by pytest but are marked BLOCKED here because they only passed on a mistyped URL's 404.
A17: Evidence: the pytest output is saved as test_output.txt and summarised on the 'Execution Proof' sheet.

Sheet Test Cases
A1: Test ID | B1: Feature | C1: Preconditions | D1: Steps | E1: Input | F1: Expected Result | G1: Actual Result | H1: Status | I1: Defect ID | J1: Evidence Link
A2: AUTH-01 | B2: Signup | C2: Default tenant (id=2) exists; user 'alice' registered unless the scenario says otherwise; fresh API client | D2: 1. Create the preconditions. 2. Send POST /signup/ with the input. 3. Compare the HTTP status and database state with the Expected Result. | E2: Valid payload creates a user in the default tenant | F2: 201 | G2: As expected - automated assertions passed (pytest run 2026-10-19) | H2: PASS | J2: test_output.txt (pytest run 2026-10-19) - paste Drive link here
A3: AUTH-02 | B3: Signup | C3: Default tenant (id=2) exists; user 'alice' registered unless the scenario says otherwise; fresh API client | D3: 1. Create the preconditions. 2. Send POST /signup/ with the input. 3. Compare the HTTP status and database state with the Expected Result. | E3: Missing username or password | F3: 400, no user created | G3: As expected - automated assertions passed (pytest run 2026-10-19) | H3: PASS | J3: test_output.txt (pytest run 2026-10-19) - paste Drive link here
A4: AUTH-03 | B4: Signup | C4: Default tenant (id=2) exists; user 'alice' registered unless the scenario says otherwise; fresh API client | D4: 1. Create the preconditions. 2. Send POST /signup/ with the input. 3. Compare the HTTP status and database state with the Expected Result. | E4: Same payload submitted twice (retry) | F4: 201 then 400, one row | G4: As expected - automated assertions passed (pytest run 2026-10-19) | H4: PASS | J4: test_output.txt (pytest run 2026-10-19) - paste Drive link here
A5: AUTH-04 | B5: Signup | C5: Default tenant (id=2) exists; user 'alice' registered unless the scenario says otherwise; fresh API client | D5: 1. Create the preconditions. 2. Send POST /signup/ with the input. 3. Compare the HTTP status and database state with the Expected Result. | E5: Username already taken by existing user | F5: 400 | G5: As expected - automated assertions passed (pytest run 2026-10-19) | H5: PASS | J5: test_output.txt (pytest run 2026-10-19) - paste Drive link here
A6: AUTH-05 | B6: Signup | C6: Default tenant (id=2) exists; user 'alice' registered unless the scenario says otherwise; fresh API client | D6: 1. Create the preconditions. 2. Send POST /signup/ with the input. 3. Compare the HTTP status and database state with the Expected Result. | E6: Malformed email | F6: 400 | G6: As expected - automated assertions passed (pytest run 2026-10-19) | H6: PASS | J6: test_output.txt (pytest run 2026-10-19) - paste Drive link here
A7: AUTH-06 | B7: Signup | C7: Default tenant (id=2) exists; user 'alice' registered unless the scenario says otherwise; fresh API client | D7: 1. Create the preconditions. 2. Send POST /signup/ with the input. 3. Compare the HTTP status and database state with the Expected Result. | E7: Username 150 chars accepted, 151 rejected | F7: 201 / 400 | G7: As expected - automated assertions passed (pytest run 2026-10-19) | H7: PASS | J7: test_output.txt (pytest run 2026-10-19) - paste Drive link here
A8: AUTH-07 | B8: Signup | C8: Default tenant (id=2) exists; user 'alice' registered unless the scenario says otherwise; fresh API client | D8: 1. Create the preconditions. 2. Send POST /signup/ with the input. 3. Compare the HTTP status and database state with the Expected Result. | E8: One-character password | F8: 400 (password validation) | G8: 201 Created - password '1' was accepted (no password validation) | H8: FAIL | I8: D-01 | J8: test_output.txt (pytest run 2026-10-19) - paste Drive link here
A9: AUTH-08 | B9: Signup | C9: Default tenant (id=2) exists; user 'alice' registered unless the scenario says otherwise; fresh API client | D9: 1. Create the preconditions. 2. Send POST /signup/ with the input. 3. Compare the HTTP status and database state with the Expected Result. | E9: Default tenant (id=2) does not exist | F9: handled error, not 500 | G9: 500 Internal Server Error - Tenant.objects.get(id=2) raised DoesNotExist | H9: FAIL | I9: D-02 | J9: test_output.txt (pytest run 2026-10-19) - paste Drive link here
A10: AUTH-09 | B10: Signup | C10: Default tenant (id=2) exists; user 'alice' registered unless the scenario says otherwise; fresh API client | D10: 1. Create the preconditions. 2. Send POST /signup/ with the input. 3. Compare the HTTP status and database state with the Expected Result. | E10: GET on signup endpoint | F10: 405 | G10: As expected - automated assertions passed (pytest run 2026-10-19) | H10: PASS | J10: test_output.txt (pytest run 2026-10-19) - paste Drive link here
A11: AUTH-10 | B11: Login | C11: Default tenant (id=2) exists; user 'alice' registered unless the scenario says otherwise; fresh API client | D11: 1. Create the preconditions. 2. Send POST /login/ with the input. 3. Compare the HTTP status and database state with the Expected Result. | E11: Valid credentials | F11: 200, httpOnly access+refresh cookies, no tokens in body | G11: As expected - automated assertions passed (pytest run 2026-10-19) | H11: PASS | J11: test_output.txt (pytest run 2026-10-19) - paste Drive link here
A12: AUTH-11 | B12: Login | C12: Default tenant (id=2) exists; user 'alice' registered unless the scenario says otherwise; fresh API client | D12: 1. Create the preconditions. 2. Send POST /login/ with the input. 3. Compare the HTTP status and database state with the Expected Result. | E12: Issued cookies contain valid JWTs for the right user | F12: decode OK | G12: As expected - automated assertions passed (pytest run 2026-10-19) | H12: PASS | J12: test_output.txt (pytest run 2026-10-19) - paste Drive link here
A13: AUTH-12 | B13: Login | C13: Default tenant (id=2) exists; user 'alice' registered unless the scenario says otherwise; fresh API client | D13: 1. Create the preconditions. 2. Send POST /login/ with the input. 3. Compare the HTTP status and database state with the Expected Result. | E13: Wrong password | F13: 401, no cookies | G13: As expected - automated assertions passed (pytest run 2026-10-19) | H13: PASS | J13: test_output.txt (pytest run 2026-10-19) - paste Drive link here
A14: AUTH-13 | B14: Login | C14: Default tenant (id=2) exists; user 'alice' registered unless the scenario says otherwise; fresh API client | D14: 1. Create the preconditions. 2. Send POST /login/ with the input. 3. Compare the HTTP status and database state with the Expected Result. | E14: Username does not exist | F14: 401 | G14: As expected - automated assertions passed (pytest run 2026-10-19) | H14: PASS | J14: test_output.txt (pytest run 2026-10-19) - paste Drive link here
A15: AUTH-14 | B15: Login | C15: Default tenant (id=2) exists; user 'alice' registered unless the scenario says otherwise; fresh API client | D15: 1. Create the preconditions. 2. Send POST /login/ with the input. 3. Compare the HTTP status and database state with the Expected Result. | E15: Missing username or password | F15: 400 | G15: As expected - automated assertions passed (pytest run 2026-10-19) | H15: PASS | J15: test_output.txt (pytest run 2026-10-19) - paste Drive link here
A16: AUTH-15 | B16: Login | C16: Default tenant (id=2) exists; user 'alice' registered unless the scenario says otherwise; fresh API client | D16: 1. Create the preconditions. 2. Send POST /login/ with the input. 3. Compare the HTTP status and database state with the Expected Result. | E16: Deactivated account | F16: 401, no cookies | G16: As expected - automated assertions passed (pytest run 2026-10-19) | H16: PASS | J16: test_output.txt (pytest run 2026-10-19) - paste Drive link here
A17: AUTH-16 | B17: Login | C17: Default tenant (id=2) exists; user 'alice' registered unless the scenario says otherwise; fresh API client | D17: 1. Create the preconditions. 2. Send POST /login/ with the input. 3. Compare the HTTP status and database state with the Expected Result. | E17: GET on login endpoint | F17: 405 | G17: As expected - automated assertions passed (pytest run 2026-10-19) | H17: PASS | J17: test_output.txt (pytest run 2026-10-19) - paste Drive link here
A18: AUTH-20 | B18: Refresh | C18: Default tenant (id=2) exists; user 'alice' registered unless the scenario says otherwise; fresh API client | D18: 1. Create the preconditions. 2. Send POST /token/refresh/ with the input. 3. Compare the HTTP status and database state with the Expected Result. | E18: Valid refresh cookie | F18: 200, new access cookie | G18: As expected - automated assertions passed (pytest run 2026-10-19) | H18: PASS | J18: test_output.txt (pytest run 2026-10-19) - paste Drive link here
A19: AUTH-21 | B19: Refresh | C19: Default tenant (id=2) exists; user 'alice' registered unless the scenario says otherwise; fresh API client | D19: 1. Create the preconditions. 2. Send POST /token/refresh/ with the input. 3. Compare the HTTP status and database state with the Expected Result. | E19: No refresh cookie | F19: 401 'Refresh token missing' | G19: As expected - automated assertions passed (pytest run 2026-10-19) | H19: PASS | J19: test_output.txt (pytest run 2026-10-19) - paste Drive link here
A20: AUTH-22 | B20: Refresh | C20: Default tenant (id=2) exists; user 'alice' registered unless the scenario says otherwise; fresh API client | D20: 1. Create the preconditions. 2. Send POST /token/refresh/ with the input. 3. Compare the HTTP status and database state with the Expected Result. | E20: Malformed token | F20: 401 'Invalid refresh token' | G20: As expected - automated assertions passed (pytest run 2026-10-19) | H20: PASS | J20: test_output.txt (pytest run 2026-10-19) - paste Drive link here
A21: AUTH-23 | B21: Refresh | C21: Default tenant (id=2) exists; user 'alice' registered unless the scenario says otherwise; fresh API client | D21: 1. Create the preconditions. 2. Send POST /token/refresh/ with the input. 3. Compare the HTTP status and database state with the Expected Result. | E21: Access token sent in refresh cookie | F21: 401 (token type check) | G21: As expected - automated assertions passed (pytest run 2026-10-19) | H21: PASS | J21: test_output.txt (pytest run 2026-10-19) - paste Drive link here
... A24: AUTH-31 | B24: Status | C24: Default tenant (id=2) exists; user 'alice' registered unless the scenario says otherwise; fresh API client | D24: 1. Create the preconditions. 2. Send GET /status/ with the input. 3. Compare the HTTP status and database state with the Expected Result. | E24: Valid access cookie | F24: 200 authenticated=true | G24: As expected - automated assertions passed (pytest run 2026-10-19) | H24: PASS | J24: test_output.txt (pytest run 2026-10-19) - paste Drive link here
A25: AUTH-32 | B25: Status | C25: Default tenant (id=2) exists; user 'alice' registered unless the scenario says otherwise; fresh API client | D25: 1. Create the preconditions. 2. Send GET /status/ with the input. 3. Compare the HTTP status and database state with the Expected Result. | E25: Malformed access cookie | F25: 200 authenticated=false | G25: 401 Unauthorized returned instead of 200 {authenticated: false} | H25: FAIL | I25: D-03 | J25: test_output.txt (pytest run 2026-10-19) - paste Drive link here
A26: AUTH-33 | B26: Status | C26: Default tenant (id=2) exists; user 'alice' registered unless the scenario says otherwise; fresh API client | D26: 1. Create the preconditions. 2. Send GET /status/ with the input. 3. Compare the HTTP status and database state with the Expected Result. | E26: Expired access cookie | F26: 200 authenticated=false | G26: 401 response has no 'authenticated' key (expected 200 {authenticated: false}) | H26: FAIL | I26: D-03 | J26: test_output.txt (pytest run 2026-10-19) - paste Drive link here
A27: AUTH-34 | B27: Status | C27: Default tenant (id=2) exists; user 'alice' registered unless the scenario says otherwise; fresh API client | D27: 1. Create the preconditions. 2. Send GET /status/ with the input. 3. Compare the HTTP status and database state with the Expected Result. | E27: Refresh token placed in access cookie | F27: authenticated=false | G27: 401 response has no 'authenticated' key (expected 200 {authenticated: false}) | H27: FAIL | I27: D-03 | J27: test_output.txt (pytest run 2026-10-19) - paste Drive link here
A28: AUTH-40 | B28: Logout | C28: Default tenant (id=2) exists; user 'alice' registered unless the scenario says otherwise; fresh API client | D28: 1. Create the preconditions. 2. Send POST /logout/ with the input. 3. Compare the HTTP status and database state with the Expected Result. | E28: Authenticated logout | F28: 200, access+refresh cookies expired | G28: As expected - automated assertions passed (pytest run 2026-10-19) | H28: PASS | J28: test_output.txt (pytest run 2026-10-19) - paste Drive link here
A29: AUTH-41 | B29: Logout | C29: Default tenant (id=2) exists; user 'alice' registered unless the scenario says otherwise; fresh API client | D29: 1. Create the preconditions. 2. Send POST /logout/ with the input. 3. Compare the HTTP status and database state with the Expected Result. | E29: GET on logout endpoint | F29: 405 | G29: As expected - automated assertions passed (pytest run 2026-10-19) | H29: PASS | J29: test_output.txt (pytest run 2026-10-19) - paste Drive link here
A30: AUTH-42 | B30: Regression flow | C30: Default tenant (id=2) exists; user 'alice' registered unless the scenario says otherwise; fresh API client | D30: 1. Create the preconditions. 2. Send the login / status / refresh / logout / cart endpoints in sequence with the input. 3. Compare the HTTP status and database state with the Expected Result. | E30: login -> status true -> logout -> status false | G30: As expected - automated assertions passed (pytest run 2026-10-19) | H30: PASS | J30: test_output.txt (pytest run 2026-10-19) - paste Drive link here
A31: AUTH-43 | B31: Regression flow | C31: Default tenant (id=2) exists; user 'alice' registered unless the scenario says otherwise; fresh API client | D31: 1. Create the preconditions. 2. Send the login / status / refresh / logout / cart endpoints in sequence with the input. 3. Compare the HTTP status and database state with the Expected Result. | E31: expired access -> status false -> refresh -> status true | G31: 401 response has no 'authenticated' key (expected 200 {authenticated: false}) | H31: FAIL | I31: D-03 | J31: test_output.txt (pytest run 2026-10-19) - paste Drive link here
A32: CART-01 | B32: Add | C32: Logged-in user in tenant A; products and stock created as the scenario states; cart empty unless stated | D32: 1. Create the preconditions. 2. Send POST add-to-cart with the input. 3. Compare the HTTP status and database state with the Expected Result. | E32: Valid product + quantity | F32: 201, item created with that quantity | G32: As expected - automated assertions passed (pytest run 2026-10-19) | H32: PASS | J32: test_output.txt (pytest run 2026-10-19) - paste Drive link here
A33: CART-02 | B33: Add | C33: Logged-in user in tenant A; products and stock created as the scenario states; cart empty unless stated | D33: 1. Create the preconditions. 2. Send POST add-to-cart with the input. 3. Compare the HTTP status and database state with the Expected Result. | E33: quantity omitted | F33: 201, quantity defaults to 1 | G33: As expected - automated assertions passed (pytest run 2026-10-19) | H33: PASS | J33: test_output.txt (pytest run 2026-10-19) - paste Drive link here
A34: CART-03 | B34: Add | C34: Logged-in user in tenant A; products and stock created as the scenario states; cart empty unless stated | D34: 1. Create the preconditions. 2. Send POST add-to-cart with the input. 3. Compare the HTTP status and database state with the Expected Result. | E34: quantity "3" (string) | F34: 201, stored as integer 3 | G34: As expected - automated assertions passed (pytest run 2026-10-19) | H34: PASS | J34: test_output.txt (pytest run 2026-10-19) - paste Drive link here
A35: CART-04 | B35: Add | C35: Logged-in user in tenant A; products and stock created as the scenario states; cart empty unless stated | D35: 1. Create the preconditions. 2. Send POST add-to-cart with the input. 3. Compare the HTTP status and database state with the Expected Result. | E35: quantity 0, -1, "abc", "1.5", null | F35: 400, nothing added | G35: As expected - automated assertions passed (pytest run 2026-10-19) | H35: PASS | J35: test_output.txt (pytest run 2026-10-19) - paste Drive link here
A36: CART-05 | B36: Add | C36: Logged-in user in tenant A; products and stock created as the scenario states; cart empty unless stated | D36: 1. Create the preconditions. 2. Send POST add-to-cart with the input. 3. Compare the HTTP status and database state with the Expected Result. | E36: Same product added twice (retry) | F36: one row, quantities summed | G36: As expected - automated assertions passed (pytest run 2026-10-19) | H36: PASS | J36: test_output.txt (pytest run 2026-10-19) - paste Drive link here
A37: CART-06 | B37: Add | C37: Logged-in user in tenant A; products and stock created as the scenario states; cart empty unless stated | D37: 1. Create the preconditions. 2. Send POST add-to-cart with the input. 3. Compare the HTTP status and database state with the Expected Result. | E37: Second add pushes total above stock | F37: 400, quantity unchanged | G37: As expected - automated assertions passed (pytest run 2026-10-19) | H37: PASS | J37: test_output.txt (pytest run 2026-10-19) - paste Drive link here
A38: CART-07 | B38: Add | C38: Logged-in user in tenant A; products and stock created as the scenario states; cart empty unless stated | D38: 1. Create the preconditions. 2. Send POST add-to-cart with the input. 3. Compare the HTTP status and database state with the Expected Result. | E38: quantity == stock | F38: 201 | G38: As expected - automated assertions passed (pytest run 2026-10-19) | H38: PASS | J38: test_output.txt (pytest run 2026-10-19) - paste Drive link here
A39: CART-08 | B39: Add | C39: Logged-in user in tenant A; products and stock created as the scenario states; cart empty unless stated | D39: 1. Create the preconditions. 2. Send POST add-to-cart with the input. 3. Compare the HTTP status and database state with the Expected Result. | E39: First add with quantity > stock | F39: 400, nothing added | G39: 201 Created - quantity above stock was accepted on the first add | H39: FAIL | I39: D-04 | J39: test_output.txt (pytest run 2026-10-19) - paste Drive link here
A40: CART-09 | B40: Add | C40: Logged-in user in tenant A; products and stock created as the scenario states; cart empty unless stated | D40: 1. Create the preconditions. 2. Send POST add-to-cart with the input. 3. Compare the HTTP status and database state with the Expected Result. | E40: Stock is 0 | F40: 400, nothing added | G40: As expected - automated assertions passed (pytest run 2026-10-19) | H40: PASS | J40: test_output.txt (pytest run 2026-10-19) - paste Drive link here
A41: CART-10 | B41: Add | C41: Logged-in user in tenant A; products and stock created as the scenario states; cart empty unless stated | D41: 1. Create the preconditions. 2. Send POST add-to-cart with the input. 3. Compare the HTTP status and database state with the Expected Result. | E41: Product has no stock record | F41: 400 'inventory not configured' | G41: As expected - automated assertions passed (pytest run 2026-10-19) | H41: PASS | J41: test_output.txt (pytest run 2026-10-19) - paste Drive link here
A42: CART-11 | B42: Add | C42: Logged-in user in tenant A; products and stock created as the scenario states; cart empty unless stated | D42: 1. Create the preconditions. 2. Send POST add-to-cart with the input. 3. Compare the HTTP status and database state with the Expected Result. | E42: Non-existent / missing product_id | F42: 404 | G42: As expected - automated assertions passed (pytest run 2026-10-19) | H42: PASS | J42: test_output.txt (pytest run 2026-10-19) - paste Drive link here
...

Sheet Defects
A1: Defect ID | B1: Title | C1: Severity | D1: Affected tests | E1: What happens | F1: Suggested fix | G1: Status
A2: D-01 | B2: Weak passwords accepted at signup | C2: Medium | D2: AUTH-07 | E2: Password '1' creates an account; RegisterSerializer never runs Django password validators. | F2: Call django.contrib.auth.password_validation.validate_password in RegisterSerializer.validate_password. | G2: Open
A3: D-02 | B3: Signup depends on hard-coded Tenant id=2 | C3: Medium | D3: AUTH-08 | E3: If tenant 2 is missing, signup crashes with HTTP 500. | F3: Look the default tenant up by name or a setting (get_or_create) and return a clean 4xx/503 if it cannot be found. | G3: Open
A4: D-03 | B4: /status/ returns 401 for expired or invalid access cookie | C4: Medium | D4: AUTH-32, 33, 34, 43 | E4: DRF authentication runs before the view, so a bad cookie gives 401 instead of {authenticated: false}. The UI cannot tell 'expired' from 'logged out' and never tries the refresh endpoint, so users appear logged out after the 15-minute access token expires. | F4: Add @authentication_classes([]) under @api_view on auth_status; in the Navbar call /token/refresh/ once when status is false. | G4: Open
A5: D-04 | B5: First add-to-cart does not check stock | C5: High | D5: CART-08 | E5: Only repeat adds are checked (inside 'if not created'), so 6 can be added when 5 are in stock. | F5: Validate quantity against available_stock before get_or_create. | G5: Open
A6: D-05 | B6: Duplicate stock record for one product causes a database error | C6: Medium | D6: INV-03 | E6: InventoryWriteSerializer declares 'product' explicitly, which drops the one-to-one uniqueness validator, so the second insert hits IntegrityError (HTTP 500). | F6: Remove the explicit field or add UniqueValidator(Inventory.objects.all()). | G6: Open
A7: D-06 | B7: Inventory API is not tenant-scoped | C7: High | D7: INV-21, 22, 23 | E7: Any user can list, edit and create stock for other tenants' products. | F7: Filter get_queryset by product__tenant=request.user.tenant and restrict the product queryset in the serializer. | G7: Open
A8: D-07 | B8: No role-based access control | C8: High | D8: INV-24, PRD-33 | E8: Any logged-in customer can create, edit and delete products and change stock. | F8: Use IsAdminUser (or a custom permission) for unsafe methods on products and inventory. | G8: Open
A9: D-08 | B9: Deleted or inactive products can still be checked out | C9: High | D9: ORD-17 | E9: Checkout never re-checks is_active / is_deleted of cart items. | F9: Reject or skip such items in checkout_order before taking stock. | G9: Open
A10: D-09 | B10: Negative prices accepted | C10: Medium | D10: PRD-27 | E10: Product price has no minimum. | F10: Add MinValueValidator(0) and a database CheckConstraint price >= 0. | G10: Open
A11: D-10 | B11: Inventory list is unordered | C11: Low | D11: INV-01, INV-21 (warning) | E11: Pagination warns about inconsistent results. | F11: Add .order_by('id') in InventoryViewSet.get_queryset. | G11: Open
A12: D-11 | B12: Cart update/remove 404 for deactivated products (suspected) | C12: Medium | D12: CART-44 | E12: update_cart_quantity and remove_cart_item filter on is_active/is_deleted, so a customer may be unable to remove such an item. Not yet confirmed because of the URL issue. | F12: Look the cart item up by cart + product without the active filter. Re-run CART-44 first. | G12: To confirm

Sheet Execution Proof
A1: pytest run 2026-10-19 - raw summary (from test_output.txt)
A3: platform win32 -- Python 3.13.7, pytest-9.1.1; Django 5.2.8; pytest-django 4.12.0; settings config.settings
A4: =35 failed, 117 passed, 2 warnings, 24 subtests passed in 208.25s (0:3:28) = -> #VALUE!
A5: (pytest counts the three failed sub-tests of CART-32 as separate failures: 149 tests in total)
A7: FAILED authen: test_auth07, test_auth08, test_auth32, test_auth33, test_auth34, test_auth43
A8: FAILED carts: test_cart08, test_cart30, test_cart31, test_cart32 (3 sub-tests), test_cart36, test_cart37, test_cart40, test_cart41, test_cart44, test_cart45, test_cart50
A9: FAILED inventory: test_inv03, test_inv21, test_inv22, test_inv23, test_inv24
A10: FAILED orders: test_ord17
A11: FAILED products: test_prd27, test_prd33
A12: FAILED rate limiter: test_rl01 ... test_rl08 (ModuleNotFoundError: No module named 'core')
A13: WARNING: UnorderedObjectListWarning on inventory.models.Inventory (inventory list endpoint)
